#include <iostream>
#include <stdexcept>

using namespace std;

double divide(double numerator, double denominator) {
    if (denominator == 0) {
        throw runtime_error("Ошибка: Деление на ноль.");
    }
    return numerator / denominator;
}

int main() {
    double num1, num2;

    try {
        cout << "Введите первое число: ";
        if (!(cin >> num1)) {
            throw invalid_argument("Ошибка: Некорректный ввод первого числа.");
        }

        cout << "Введите второе число: ";
        if (!(cin >> num2)) {
            throw invalid_argument("Ошибка: Некорректный ввод второго числа.");
        }

        double result = divide(num1, num2);
        cout << "Результат деления: " << result << endl;

    } catch (const runtime_error& e) {
        cout << e.what() << endl;
    } catch (const invalid_argument& e) {
        cout << e.what() << endl;
    } catch (...) {
        cout << "Произошла неожиданная ошибка." << endl;
    }

}
